Workbook

Sheet Instructions
A1: Toastie Costing System
A3: How to use
A4: 1. Update purchase quantities and prices in the Ingredients sheet.
A5: 2. Update per-serving ingredient quantities in the Recipe Usage sheet if your recipe changes.
A6: 3. Enter your chosen selling price in the Recipe Usage sheet.
A7: 4. Review Product Summary for capital per serving, packaging cost, profit, and actual margin.
A8: 5. Review Margin Pricing for exact and rounded selling price options from 20% to 50% margin.
A9: 6. Yellow cells are editable inputs. Green cells are formulas that recalculate automatically in Excel or Google Sheets.
A11: Current assumptions
A12: 1 baguette = 7 servings.
A13: Garlic Cheese Toasties use baguette, butter, garlic, cheese, parmesan, and fresh parsley.
A14: Sugar Rush Toasties use baguette, butter, and brown sugar.
... A22: Formula color guide
A23: Yellow | B23: Input cells: enter prices, purchase quantities, recipe quantities, and chosen selling price.
A24: Green | B24: Formula cells: calculated automatically.
A25: Blue | B25: Table headers.
A26: Orange | B26: Notes and assumptions.

Sheet Ingredients
A1: Ingredient | B1: Measurement Unit | C1: Purchase Qty | D1: Purchase Cost | E1: Cost Per Unit | F1: Notes
A2: Baguette | B2: pc | C2: 1 | D2: 85 | E2: =IF(OR(C2="",D2=""),"",D2/C2) | F2: 1 baguette is used as 7 toastie servings.
A3: Butter | B3: g | C3: 200 | D3: 49 | E3: =IF(OR(C3="",D3=""),"",D3/C3) | F3: Purchase pack is 200g.
A4: Garlic | B4: bulb | C4: 7 | D4: 35 | E4: =IF(OR(C4="",D4=""),"",D4/C4) | F4: Purchase pack has 7 bulbs.
A5: Cheese | B5: g | C5: 185 | D5: 90 | E5: =IF(OR(C5="",D5=""),"",D5/C5) | F5: Default recipe assumes the 185g pack covers 10 servings.
A6: Parmesan Cheese | B6: g | C6: 350 | D6: 212 | E6: =IF(OR(C6="",D6=""),"",D6/C6) | F6: 1/4 cup parmesan is estimated as 25g for 10 servings.
A7: Parsley | B7: g | C7: 100 | D7: 40 | E7: =IF(OR(C7="",D7=""),"",D7/C7) | F7: Fresh chopped parsley estimate: 1 tbsp = 3.8g.
A8: Brown Sugar | B8: g | C8: 250 | D8: 20 | E8: =IF(OR(C8="",D8=""),"",D8/C8) | F8: 250g sugar covers 25 Sugar Rush servings.
A9: Takeout Box | B9: pc | C9: 10 | D9: 70 | E9: =IF(OR(C9="",D9=""),"",D9/C9) | F9: Optional packaging: 1 box per serving.
A10: Dine-in Box | B10: pc | C10: 25 | D10: 60 | E10: =IF(OR(C10="",D10=""),"",D10/C10) | F10: Optional packaging: 1 box per serving.

Sheet Recipe Usage
A1: Product | B1: Package Option | C1: Selling Price | D1: Baguette (pc) | E1: Butter (g) | F1: Garlic (bulb) | G1: Cheese (g) | H1: Parmesan Cheese (g) | I1: Parsley (g) | J1: Brown Sugar (g) | K1: Takeout Box (pc) | L1: Dine-in Box (pc)
A2: Garlic Cheese Toasties | B2: No Box | D2: 0.14285714 | E2: 11.3 | F2: 0.4 | G2: 18.5 | H2: 2.5 | I2: 1.14 | J2: 0 | K2: 0 | L2: 0
A3: Garlic Cheese Toasties | B3: Dine-in | D3: 0.14285714 | E3: 11.3 | F3: 0.4 | G3: 18.5 | H3: 2.5 | I3: 1.14 | J3: 0 | K3: 0 | L3: 1
A4: Garlic Cheese Toasties | B4: Takeout | D4: 0.14285714 | E4: 11.3 | F4: 0.4 | G4: 18.5 | H4: 2.5 | I4: 1.14 | J4: 0 | K4: 1 | L4: 0
A5: Sugar Rush Toasties | B5: No Box | D5: 0.14285714 | E5: 10 | F5: 0 | G5: 0 | H5: 0 | I5: 0 | J5: 10 | K5: 0 | L5: 0
A6: Sugar Rush Toasties | B6: Dine-in | D6: 0.14285714 | E6: 10 | F6: 0 | G6: 0 | H6: 0 | I6: 0 | J6: 10 | K6: 0 | L6: 1
A7: Sugar Rush Toasties | B7: Takeout | D7: 0.14285714 | E7: 10 | F7: 0 | G7: 0 | H7: 0 | I7: 0 | J7: 10 | K7: 1 | L7: 0

Sheet Cost Breakdown
A1: Product | B1: Package Option | C1: Selling Price | D1: Ingredient | E1: Quantity | F1: Unit | G1: Cost Per Unit | H1: Ingredient Cost
A2: Garlic Cheese Toasties | B2: No Box | C2: ='Recipe Usage'!C2 | D2: Baguette | E2: ='Recipe Usage'!D2 | F2: pc | G2: =IFERROR(VLOOKUP(D2,'Ingredients'!$A$2:$E$10,5,FALSE),"") | H2: =IF(OR(E2=0,G2=""),0,E2*G2)
A3: Garlic Cheese Toasties | B3: No Box | C3: ='Recipe Usage'!C2 | D3: Butter | E3: ='Recipe Usage'!E2 | F3: g | G3: =IFERROR(VLOOKUP(D3,'Ingredients'!$A$2:$E$10,5,FALSE),"") | H3: =IF(OR(E3=0,G3=""),0,E3*G3)
A4: Garlic Cheese Toasties | B4: No Box | C4: ='Recipe Usage'!C2 | D4: Garlic | E4: ='Recipe Usage'!F2 | F4: bulb | G4: =IFERROR(VLOOKUP(D4,'Ingredients'!$A$2:$E$10,5,FALSE),"") | H4: =IF(OR(E4=0,G4=""),0,E4*G4)
A5: Garlic Cheese Toasties | B5: No Box | C5: ='Recipe Usage'!C2 | D5: Cheese | E5: ='Recipe Usage'!G2 | F5: g | G5: =IFERROR(VLOOKUP(D5,'Ingredients'!$A$2:$E$10,5,FALSE),"") | H5: =IF(OR(E5=0,G5=""),0,E5*G5)
A6: Garlic Cheese Toasties | B6: No Box | C6: ='Recipe Usage'!C2 | D6: Parmesan Cheese | E6: ='Recipe Usage'!H2 | F6: g | G6: =IFERROR(VLOOKUP(D6,'Ingredients'!$A$2:$E$10,5,FALSE),"") | H6: =IF(OR(E6=0,G6=""),0,E6*G6)
A7: Garlic Cheese Toasties | B7: No Box | C7: ='Recipe Usage'!C2 | D7: Parsley | E7: ='Recipe Usage'!I2 | F7: g | G7: =IFERROR(VLOOKUP(D7,'Ingredients'!$A$2:$E$10,5,FALSE),"") | H7: =IF(OR(E7=0,G7=""),0,E7*G7)
A8: Garlic Cheese Toasties | B8: No Box | C8: ='Recipe Usage'!C2 | D8: Brown Sugar | E8: ='Recipe Usage'!J2 | F8: g | G8: =IFERROR(VLOOKUP(D8,'Ingredients'!$A$2:$E$10,5,FALSE),"") | H8: =IF(OR(E8=0,G8=""),0,E8*G8)
A9: Garlic Cheese Toasties | B9: No Box | C9: ='Recipe Usage'!C2 | D9: Takeout Box | E9: ='Recipe Usage'!K2 | F9: pc | G9: =IFERROR(VLOOKUP(D9,'Ingredients'!$A$2:$E$10,5,FALSE),"") | H9: =IF(OR(E9=0,G9=""),0,E9*G9)
A10: Garlic Cheese Toasties | B10: No Box | C10: ='Recipe Usage'!C2 | D10: Dine-in Box | E10: ='Recipe Usage'!L2 | F10: pc | G10: =IFERROR(VLOOKUP(D10,'Ingredients'!$A$2:$E$10,5,FALSE),"") | H10: =IF(OR(E10=0,G10=""),0,E10*G10)
A11: Garlic Cheese Toasties | B11: Dine-in | C11: ='Recipe Usage'!C3 | D11: Baguette | E11: ='Recipe Usage'!D3 | F11: pc | G11: =IFERROR(VLOOKUP(D11,'Ingredients'!$A$2:$E$10,5,FALSE),"") | H11: =IF(OR(E11=0,G11=""),0,E11*G11)
A12: Garlic Cheese Toasties | B12: Dine-in | C12: ='Recipe Usage'!C3 | D12: Butter | E12: ='Recipe Usage'!E3 | F12: g | G12: =IFERROR(VLOOKUP(D12,'Ingredients'!$A$2:$E$10,5,FALSE),"") | H12: =IF(OR(E12=0,G12=""),0,E12*G12)
A13: Garlic Cheese Toasties | B13: Dine-in | C13: ='Recipe Usage'!C3 | D13: Garlic | E13: ='Recipe Usage'!F3 | F13: bulb | G13: =IFERROR(VLOOKUP(D13,'Ingredients'!$A$2:$E$10,5,FALSE),"") | H13: =IF(OR(E13=0,G13=""),0,E13*G13)
A14: Garlic Cheese Toasties | B14: Dine-in | C14: ='Recipe Usage'!C3 | D14: Cheese | E14: ='Recipe Usage'!G3 | F14: g | G14: =IFERROR(VLOOKUP(D14,'Ingredients'!$A$2:$E$10,5,FALSE),"") | H14: =IF(OR(E14=0,G14=""),0,E14*G14)
A15: Garlic Cheese Toasties | B15: Dine-in | C15: ='Recipe Usage'!C3 | D15: Parmesan Cheese | E15: ='Recipe Usage'!H3 | F15: g | G15: =IFERROR(VLOOKUP(D15,'Ingredients'!$A$2:$E$10,5,FALSE),"") | H15: =IF(OR(E15=0,G15=""),0,E15*G15)
A16: Garlic Cheese Toasties | B16: Dine-in | C16: ='Recipe Usage'!C3 | D16: Parsley | E16: ='Recipe Usage'!I3 | F16: g | G16: =IFERROR(VLOOKUP(D16,'Ingredients'!$A$2:$E$10,5,FALSE),"") | H16: =IF(OR(E16=0,G16=""),0,E16*G16)
A17: Garlic Cheese Toasties | B17: Dine-in | C17: ='Recipe Usage'!C3 | D17: Brown Sugar | E17: ='Recipe Usage'!J3 | F17: g | G17: =IFERROR(VLOOKUP(D17,'Ingredients'!$A$2:$E$10,5,FALSE),"") | H17: =IF(OR(E17=0,G17=""),0,E17*G17)
A18: Garlic Cheese Toasties | B18: Dine-in | C18: ='Recipe Usage'!C3 | D18: Takeout Box | E18: ='Recipe Usage'!K3 | F18: pc | G18: =IFERROR(VLOOKUP(D18,'Ingredients'!$A$2:$E$10,5,FALSE),"") | H18: =IF(OR(E18=0,G18=""),0,E18*G18)
A19: Garlic Cheese Toasties | B19: Dine-in | C19: ='Recipe Usage'!C3 | D19: Dine-in Box | E19: ='Recipe Usage'!L3 | F19: pc | G19: =IFERROR(VLOOKUP(D19,'Ingredients'!$A$2:$E$10,5,FALSE),"") | H19: =IF(OR(E19=0,G19=""),0,E19*G19)
A20: Garlic Cheese Toasties | B20: Takeout | C20: ='Recipe Usage'!C4 | D20: Baguette | E20: ='Recipe Usage'!D4 | F20: pc | G20: =IFERROR(VLOOKUP(D20,'Ingredients'!$A$2:$E$10,5,FALSE),"") | H20: =IF(OR(E20=0,G20=""),0,E20*G20)
A21: Garlic Cheese Toasties | B21: Takeout | C21: ='Recipe Usage'!C4 | D21: Butter | E21: ='Recipe Usage'!E4 | F21: g | G21: =IFERROR(VLOOKUP(D21,'Ingredients'!$A$2:$E$10,5,FALSE),"") | H21: =IF(OR(E21=0,G21=""),0,E21*G21)
A22: Garlic Cheese Toasties | B22: Takeout | C22: ='Recipe Usage'!C4 | D22: Garlic | E22: ='Recipe Usage'!F4 | F22: bulb | G22: =IFERROR(VLOOKUP(D22,'Ingredients'!$A$2:$E$10,5,FALSE),"") | H22: =IF(OR(E22=0,G22=""),0,E22*G22)
A23: Garlic Cheese Toasties | B23: Takeout | C23: ='Recipe Usage'!C4 | D23: Cheese | E23: ='Recipe Usage'!G4 | F23: g | G23: =IFERROR(VLOOKUP(D23,'Ingredients'!$A$2:$E$10,5,FALSE),"") | H23: =IF(OR(E23=0,G23=""),0,E23*G23)
A24: Garlic Cheese Toasties | B24: Takeout | C24: ='Recipe Usage'!C4 | D24: Parmesan Cheese | E24: ='Recipe Usage'!H4 | F24: g | G24: =IFERROR(VLOOKUP(D24,'Ingredients'!$A$2:$E$10,5,FALSE),"") | H24: =IF(OR(E24=0,G24=""),0,E24*G24)
A25: Garlic Cheese Toasties | B25: Takeout | C25: ='Recipe Usage'!C4 | D25: Parsley | E25: ='Recipe Usage'!I4 | F25: g | G25: =IFERROR(VLOOKUP(D25,'Ingredients'!$A$2:$E$10,5,FALSE),"") | H25: =IF(OR(E25=0,G25=""),0,E25*G25)
A26: Garlic Cheese Toasties | B26: Takeout | C26: ='Recipe Usage'!C4 | D26: Brown Sugar | E26: ='Recipe Usage'!J4 | F26: g | G26: =IFERROR(VLOOKUP(D26,'Ingredients'!$A$2:$E$10,5,FALSE),"") | H26: =IF(OR(E26=0,G26=""),0,E26*G26)
A27: Garlic Cheese Toasties | B27: Takeout | C27: ='Recipe Usage'!C4 | D27: Takeout Box | E27: ='Recipe Usage'!K4 | F27: pc | G27: =IFERROR(VLOOKUP(D27,'Ingredients'!$A$2:$E$10,5,FALSE),"") | H27: =IF(OR(E27=0,G27=""),0,E27*G27)
A28: Garlic Cheese Toasties | B28: Takeout | C28: ='Recipe Usage'!C4 | D28: Dine-in Box | E28: ='Recipe Usage'!L4 | F28: pc | G28: =IFERROR(VLOOKUP(D28,'Ingredients'!$A$2:$E$10,5,FALSE),"") | H28: =IF(OR(E28=0,G28=""),0,E28*G28)
A29: Sugar Rush Toasties | B29: No Box | C29: ='Recipe Usage'!C5 | D29: Baguette | E29: ='Recipe Usage'!D5 | F29: pc | G29: =IFERROR(VLOOKUP(D29,'Ingredients'!$A$2:$E$10,5,FALSE),"") | H29: =IF(OR(E29=0,G29=""),0,E29*G29)
A30: Sugar Rush Toasties | B30: No Box | C30: ='Recipe Usage'!C5 | D30: Butter | E30: ='Recipe Usage'!E5 | F30: g | G30: =IFERROR(VLOOKUP(D30,'Ingredients'!$A$2:$E$10,5,FALSE),"") | H30: =IF(OR(E30=0,G30=""),0,E30*G30)
A31: Sugar Rush Toasties | B31: No Box | C31: ='Recipe Usage'!C5 | D31: Garlic | E31: ='Recipe Usage'!F5 | F31: bulb | G31: =IFERROR(VLOOKUP(D31,'Ingredients'!$A$2:$E$10,5,FALSE),"") | H31: =IF(OR(E31=0,G31=""),0,E31*G31)
A32: Sugar Rush Toasties | B32: No Box | C32: ='Recipe Usage'!C5 | D32: Cheese | E32: ='Recipe Usage'!G5 | F32: g | G32: =IFERROR(VLOOKUP(D32,'Ingredients'!$A$2:$E$10,5,FALSE),"") | H32: =IF(OR(E32=0,G32=""),0,E32*G32)
A33: Sugar Rush Toasties | B33: No Box | C33: ='Recipe Usage'!C5 | D33: Parmesan Cheese | E33: ='Recipe Usage'!H5 | F33: g | G33: =IFERROR(VLOOKUP(D33,'Ingredients'!$A$2:$E$10,5,FALSE),"") | H33: =IF(OR(E33=0,G33=""),0,E33*G33)
A34: Sugar Rush Toasties | B34: No Box | C34: ='Recipe Usage'!C5 | D34: Parsley | E34: ='Recipe Usage'!I5 | F34: g | G34: =IFERROR(VLOOKUP(D34,'Ingredients'!$A$2:$E$10,5,FALSE),"") | H34: =IF(OR(E34=0,G34=""),0,E34*G34)
A35: Sugar Rush Toasties | B35: No Box | C35: ='Recipe Usage'!C5 | D35: Brown Sugar | E35: ='Recipe Usage'!J5 | F35: g | G35: =IFERROR(VLOOKUP(D35,'Ingredients'!$A$2:$E$10,5,FALSE),"") | H35: =IF(OR(E35=0,G35=""),0,E35*G35)
A36: Sugar Rush Toasties | B36: No Box | C36: ='Recipe Usage'!C5 | D36: Takeout Box | E36: ='Recipe Usage'!K5 | F36: pc | G36: =IFERROR(VLOOKUP(D36,'Ingredients'!$A$2:$E$10,5,FALSE),"") | H36: =IF(OR(E36=0,G36=""),0,E36*G36)
A37: Sugar Rush Toasties | B37: No Box | C37: ='Recipe Usage'!C5 | D37: Dine-in Box | E37: ='Recipe Usage'!L5 | F37: pc | G37: =IFERROR(VLOOKUP(D37,'Ingredients'!$A$2:$E$10,5,FALSE),"") | H37: =IF(OR(E37=0,G37=""),0,E37*G37)
A38: Sugar Rush Toasties | B38: Dine-in | C38: ='Recipe Usage'!C6 | D38: Baguette | E38: ='Recipe Usage'!D6 | F38: pc | G38: =IFERROR(VLOOKUP(D38,'Ingredients'!$A$2:$E$10,5,FALSE),"") | H38: =IF(OR(E38=0,G38=""),0,E38*G38)
A39: Sugar Rush Toasties | B39: Dine-in | C39: ='Recipe Usage'!C6 | D39: Butter | E39: ='Recipe Usage'!E6 | F39: g | G39: =IFERROR(VLOOKUP(D39,'Ingredients'!$A$2:$E$10,5,FALSE),"") | H39: =IF(OR(E39=0,G39=""),0,E39*G39)
A40: Sugar Rush Toasties | B40: Dine-in | C40: ='Recipe Usage'!C6 | D40: Garlic | E40: ='Recipe Usage'!F6 | F40: bulb | G40: =IFERROR(VLOOKUP(D40,'Ingredients'!$A$2:$E$10,5,FALSE),"") | H40: =IF(OR(E40=0,G40=""),0,E40*G40)
...

Sheet Product Summary
A1: Product | B1: Package Option | C1: Selling Price | D1: Food Cost | E1: Packaging Cost | F1: Capital Per Serving | G1: Profit | H1: Margin % | I1: Capital % of Price | J1: Missing Cost Inputs | K1: Status
A2: Garlic Cheese Toasties | B2: No Box | C2: ='Recipe Usage'!C2 | D2: =SUMIFS('Cost Breakdown'!$H:$H,'Cost Breakdown'!$A:$A,A2,'Cost Breakdown'!$B:$B,B2,'Cost Breakdown'!$D:$D,"<>Takeout Box",'Cost Breakdown'!$D:$D,"<>Dine-in Box") | E2: =SUMIFS('Cost Breakdown'!$H:$H,'Cost Breakdown'!$A:$A,A2,'Cost Breakdown'!$B:$B,B2,'Cost Breakdown'!$D:$D,"Takeout Box")+SUMIFS('Cost Breakdown'!$H:$H,'Cost Breakdown'!$A:$A,A2,'Cost Breakdown'!$B:$B,B2,'Cost Breakdown'!$D:$D,"Dine-in Box") | F2: =D2+E2 | G2: =IF(C2="","",C2-F2) | H2: =IF(OR(C2="",C2=0),"",G2/C2) | I2: =IF(OR(C2="",C2=0),"",F2/C2) | J2: =COUNTIFS('Cost Breakdown'!$A:$A,A2,'Cost Breakdown'!$B:$B,B2,'Cost Breakdown'!$E:$E,">0",'Cost Breakdown'!$G:$G,"") | K2: =IF(J2=0,"Complete","Enter missing unit costs")
A3: Garlic Cheese Toasties | B3: Dine-in | C3: ='Recipe Usage'!C3 | D3: =SUMIFS('Cost Breakdown'!$H:$H,'Cost Breakdown'!$A:$A,A3,'Cost Breakdown'!$B:$B,B3,'Cost Breakdown'!$D:$D,"<>Takeout Box",'Cost Breakdown'!$D:$D,"<>Dine-in Box") | E3: =SUMIFS('Cost Breakdown'!$H:$H,'Cost Breakdown'!$A:$A,A3,'Cost Breakdown'!$B:$B,B3,'Cost Breakdown'!$D:$D,"Takeout Box")+SUMIFS('Cost Breakdown'!$H:$H,'Cost Breakdown'!$A:$A,A3,'Cost Breakdown'!$B:$B,B3,'Cost Breakdown'!$D:$D,"Dine-in Box") | F3: =D3+E3 | G3: =IF(C3="","",C3-F3) | H3: =IF(OR(C3="",C3=0),"",G3/C3) | I3: =IF(OR(C3="",C3=0),"",F3/C3) | J3: =COUNTIFS('Cost Breakdown'!$A:$A,A3,'Cost Breakdown'!$B:$B,B3,'Cost Breakdown'!$E:$E,">0",'Cost Breakdown'!$G:$G,"") | K3: =IF(J3=0,"Complete","Enter missing unit costs")
A4: Garlic Cheese Toasties | B4: Takeout | C4: ='Recipe Usage'!C4 | D4: =SUMIFS('Cost Breakdown'!$H:$H,'Cost Breakdown'!$A:$A,A4,'Cost Breakdown'!$B:$B,B4,'Cost Breakdown'!$D:$D,"<>Takeout Box",'Cost Breakdown'!$D:$D,"<>Dine-in Box") | E4: =SUMIFS('Cost Breakdown'!$H:$H,'Cost Breakdown'!$A:$A,A4,'Cost Breakdown'!$B:$B,B4,'Cost Breakdown'!$D:$D,"Takeout Box")+SUMIFS('Cost Breakdown'!$H:$H,'Cost Breakdown'!$A:$A,A4,'Cost Breakdown'!$B:$B,B4,'Cost Breakdown'!$D:$D,"Dine-in Box") | F4: =D4+E4 | G4: =IF(C4="","",C4-F4) | H4: =IF(OR(C4="",C4=0),"",G4/C4) | I4: =IF(OR(C4="",C4=0),"",F4/C4) | J4: =COUNTIFS('Cost Breakdown'!$A:$A,A4,'Cost Breakdown'!$B:$B,B4,'Cost Breakdown'!$E:$E,">0",'Cost Breakdown'!$G:$G,"") | K4: =IF(J4=0,"Complete","Enter missing unit costs")
A5: Sugar Rush Toasties | B5: No Box | C5: ='Recipe Usage'!C5 | D5: =SUMIFS('Cost Breakdown'!$H:$H,'Cost Breakdown'!$A:$A,A5,'Cost Breakdown'!$B:$B,B5,'Cost Breakdown'!$D:$D,"<>Takeout Box",'Cost Breakdown'!$D:$D,"<>Dine-in Box") | E5: =SUMIFS('Cost Breakdown'!$H:$H,'Cost Breakdown'!$A:$A,A5,'Cost Breakdown'!$B:$B,B5,'Cost Breakdown'!$D:$D,"Takeout Box")+SUMIFS('Cost Breakdown'!$H:$H,'Cost Breakdown'!$A:$A,A5,'Cost Breakdown'!$B:$B,B5,'Cost Breakdown'!$D:$D,"Dine-in Box") | F5: =D5+E5 | G5: =IF(C5="","",C5-F5) | H5: =IF(OR(C5="",C5=0),"",G5/C5) | I5: =IF(OR(C5="",C5=0),"",F5/C5) | J5: =COUNTIFS('Cost Breakdown'!$A:$A,A5,'Cost Breakdown'!$B:$B,B5,'Cost Breakdown'!$E:$E,">0",'Cost Breakdown'!$G:$G,"") | K5: =IF(J5=0,"Complete","Enter missing unit costs")
A6: Sugar Rush Toasties | B6: Dine-in | C6: ='Recipe Usage'!C6 | D6: =SUMIFS('Cost Breakdown'!$H:$H,'Cost Breakdown'!$A:$A,A6,'Cost Breakdown'!$B:$B,B6,'Cost Breakdown'!$D:$D,"<>Takeout Box",'Cost Breakdown'!$D:$D,"<>Dine-in Box") | E6: =SUMIFS('Cost Breakdown'!$H:$H,'Cost Breakdown'!$A:$A,A6,'Cost Breakdown'!$B:$B,B6,'Cost Breakdown'!$D:$D,"Takeout Box")+SUMIFS('Cost Breakdown'!$H:$H,'Cost Breakdown'!$A:$A,A6,'Cost Breakdown'!$B:$B,B6,'Cost Breakdown'!$D:$D,"Dine-in Box") | F6: =D6+E6 | G6: =IF(C6="","",C6-F6) | H6: =IF(OR(C6="",C6=0),"",G6/C6) | I6: =IF(OR(C6="",C6=0),"",F6/C6) | J6: =COUNTIFS('Cost Breakdown'!$A:$A,A6,'Cost Breakdown'!$B:$B,B6,'Cost Breakdown'!$E:$E,">0",'Cost Breakdown'!$G:$G,"") | K6: =IF(J6=0,"Complete","Enter missing unit costs")
A7: Sugar Rush Toasties | B7: Takeout | C7: ='Recipe Usage'!C7 | D7: =SUMIFS('Cost Breakdown'!$H:$H,'Cost Breakdown'!$A:$A,A7,'Cost Breakdown'!$B:$B,B7,'Cost Breakdown'!$D:$D,"<>Takeout Box",'Cost Breakdown'!$D:$D,"<>Dine-in Box") | E7: =SUMIFS('Cost Breakdown'!$H:$H,'Cost Breakdown'!$A:$A,A7,'Cost Breakdown'!$B:$B,B7,'Cost Breakdown'!$D:$D,"Takeout Box")+SUMIFS('Cost Breakdown'!$H:$H,'Cost Breakdown'!$A:$A,A7,'Cost Breakdown'!$B:$B,B7,'Cost Breakdown'!$D:$D,"Dine-in Box") | F7: =D7+E7 | G7: =IF(C7="","",C7-F7) | H7: =IF(OR(C7="",C7=0),"",G7/C7) | I7: =IF(OR(C7="",C7=0),"",F7/C7) | J7: =COUNTIFS('Cost Breakdown'!$A:$A,A7,'Cost Breakdown'!$B:$B,B7,'Cost Breakdown'!$E:$E,">0",'Cost Breakdown'!$G:$G,"") | K7: =IF(J7=0,"Complete","Enter missing unit costs")

Sheet Margin Pricing
A1: Product | B1: Package Option | C1: Capital Per Serving | D1: 20% Margin Exact Price | E1: 20% Margin Rounded Up | F1: 25% Margin Exact Price | G1: 25% Margin Rounded Up | H1: 30% Margin Exact Price | I1: 30% Margin Rounded Up | J1: 35% Margin Exact Price | K1: 35% Margin Rounded Up | L1: 40% Margin Exact Price | M1: 40% Margin Rounded Up | N1: 45% Margin Exact Price | O1: 45% Margin Rounded Up | P1: 50% Margin Exact Price | Q1: 50% Margin Rounded Up
A2: Garlic Cheese Toasties | B2: No Box | C2: ='Product Summary'!F2 | D2: =IF($C2="","",$C2/(1-0.2)) | E2: =IF(D2="","",ROUNDUP(D2,0)) | F2: =IF($C2="","",$C2/(1-0.25)) | G2: =IF(F2="","",ROUNDUP(F2,0)) | H2: =IF($C2="","",$C2/(1-0.3)) | I2: =IF(H2="","",ROUNDUP(H2,0)) | J2: =IF($C2="","",$C2/(1-0.35)) | K2: =IF(J2="","",ROUNDUP(J2,0)) | L2: =IF($C2="","",$C2/(1-0.4)) | M2: =IF(L2="","",ROUNDUP(L2,0)) | N2: =IF($C2="","",$C2/(1-0.45)) | O2: =IF(N2="","",ROUNDUP(N2,0)) | P2: =IF($C2="","",$C2/(1-0.5)) | Q2: =IF(P2="","",ROUNDUP(P2,0))
A3: Garlic Cheese Toasties | B3: Dine-in | C3: ='Product Summary'!F3 | D3: =IF($C3="","",$C3/(1-0.2)) | E3: =IF(D3="","",ROUNDUP(D3,0)) | F3: =IF($C3="","",$C3/(1-0.25)) | G3: =IF(F3="","",ROUNDUP(F3,0)) | H3: =IF($C3="","",$C3/(1-0.3)) | I3: =IF(H3="","",ROUNDUP(H3,0)) | J3: =IF($C3="","",$C3/(1-0.35)) | K3: =IF(J3="","",ROUNDUP(J3,0)) | L3: =IF($C3="","",$C3/(1-0.4)) | M3: =IF(L3="","",ROUNDUP(L3,0)) | N3: =IF($C3="","",$C3/(1-0.45)) | O3: =IF(N3="","",ROUNDUP(N3,0)) | P3: =IF($C3="","",$C3/(1-0.5)) | Q3: =IF(P3="","",ROUNDUP(P3,0))
A4: Garlic Cheese Toasties | B4: Takeout | C4: ='Product Summary'!F4 | D4: =IF($C4="","",$C4/(1-0.2)) | E4: =IF(D4="","",ROUNDUP(D4,0)) | F4: =IF($C4="","",$C4/(1-0.25)) | G4: =IF(F4="","",ROUNDUP(F4,0)) | H4: =IF($C4="","",$C4/(1-0.3)) | I4: =IF(H4="","",ROUNDUP(H4,0)) | J4: =IF($C4="","",$C4/(1-0.35)) | K4: =IF(J4="","",ROUNDUP(J4,0)) | L4: =IF($C4="","",$C4/(1-0.4)) | M4: =IF(L4="","",ROUNDUP(L4,0)) | N4: =IF($C4="","",$C4/(1-0.45)) | O4: =IF(N4="","",ROUNDUP(N4,0)) | P4: =IF($C4="","",$C4/(1-0.5)) | Q4: =IF(P4="","",ROUNDUP(P4,0))
A5: Sugar Rush Toasties | B5: No Box | C5: ='Product Summary'!F5 | D5: =IF($C5="","",$C5/(1-0.2)) | E5: =IF(D5="","",ROUNDUP(D5,0)) | F5: =IF($C5="","",$C5/(1-0.25)) | G5: =IF(F5="","",ROUNDUP(F5,0)) | H5: =IF($C5="","",$C5/(1-0.3)) | I5: =IF(H5="","",ROUNDUP(H5,0)) | J5: =IF($C5="","",$C5/(1-0.35)) | K5: =IF(J5="","",ROUNDUP(J5,0)) | L5: =IF($C5="","",$C5/(1-0.4)) | M5: =IF(L5="","",ROUNDUP(L5,0)) | N5: =IF($C5="","",$C5/(1-0.45)) | O5: =IF(N5="","",ROUNDUP(N5,0)) | P5: =IF($C5="","",$C5/(1-0.5)) | Q5: =IF(P5="","",ROUNDUP(P5,0))
A6: Sugar Rush Toasties | B6: Dine-in | C6: ='Product Summary'!F6 | D6: =IF($C6="","",$C6/(1-0.2)) | E6: =IF(D6="","",ROUNDUP(D6,0)) | F6: =IF($C6="","",$C6/(1-0.25)) | G6: =IF(F6="","",ROUNDUP(F6,0)) | H6: =IF($C6="","",$C6/(1-0.3)) | I6: =IF(H6="","",ROUNDUP(H6,0)) | J6: =IF($C6="","",$C6/(1-0.35)) | K6: =IF(J6="","",ROUNDUP(J6,0)) | L6: =IF($C6="","",$C6/(1-0.4)) | M6: =IF(L6="","",ROUNDUP(L6,0)) | N6: =IF($C6="","",$C6/(1-0.45)) | O6: =IF(N6="","",ROUNDUP(N6,0)) | P6: =IF($C6="","",$C6/(1-0.5)) | Q6: =IF(P6="","",ROUNDUP(P6,0))
A7: Sugar Rush Toasties | B7: Takeout | C7: ='Product Summary'!F7 | D7: =IF($C7="","",$C7/(1-0.2)) | E7: =IF(D7="","",ROUNDUP(D7,0)) | F7: =IF($C7="","",$C7/(1-0.25)) | G7: =IF(F7="","",ROUNDUP(F7,0)) | H7: =IF($C7="","",$C7/(1-0.3)) | I7: =IF(H7="","",ROUNDUP(H7,0)) | J7: =IF($C7="","",$C7/(1-0.35)) | K7: =IF(J7="","",ROUNDUP(J7,0)) | L7: =IF($C7="","",$C7/(1-0.4)) | M7: =IF(L7="","",ROUNDUP(L7,0)) | N7: =IF($C7="","",$C7/(1-0.45)) | O7: =IF(N7="","",ROUNDUP(N7,0)) | P7: =IF($C7="","",$C7/(1-0.5)) | Q7: =IF(P7="","",ROUNDUP(P7,0))
